Final: **False**

Reasoning:
The original assessment identified a logical error in the way the program handles the counts for the characters. Specifically, the issue lies in the following part of `func_9`:

```python
res = [x for x in dp[n]]
for i in range(m):
    x = p[i]
    for j in range(26):
        res[j] += dp[x][j]
```

This code correctly adds the counts for the characters up to the mistake points (`p[i]`) but fails to account for the fact that the final successful attempt should also be included in the total count. This means that the final successful attempt's characters are not being counted correctly.

To illustrate this, consider the following test case:

```
1
4 2
abca
1 3
```

- First wrong try: "a" (mistake after 1st character)
- Second wrong try: "abc" (mistake after 3rd character)
- Final successful try: "abca"

The expected output should be:
```
4 2 2 0 0 0 0 0 0 0 0 0 0 0 0 0 0 0 0 0 0 0 0 0 0 0
```

However, the current program will output:
```
3 2 2 0 0 0 0 0 0 0 0 0 0 0 0 0 0 0 0 0 0 0 0 0 0 0
```

This is because the final successful attempt "abca" is not fully counted. The character 'a' in the final attempt is missed, leading to an incorrect count.

To fix this, the final successful attempt should be added to the result:

```python
res = [x for x in dp[n]]
for i in range(m):
    x = p[i]
    for j in range(26):
        res[j] += dp[x][j]
for j in range(26):
    res[j] += dp[n][j]
```

With this correction, the program will correctly count the characters for all attempts, including the final successful one.

Given the above reasoning, the original assessment is accurate, and the program is indeed incorrect. Therefore, the final assessment is:

Final: **False**